2023-10-11 12:26:11,261 DEBUG    root            Loaded Command Group: ['gcloud', 'projects']
2023-10-11 12:26:11,263 DEBUG    root            Loaded Command Group: ['gcloud', 'projects', 'describe']
2023-10-11 12:26:11,264 DEBUG    root            Running [gcloud.projects.describe] with arguments: [--account: "s-nakaue@glad-cube.com", --configuration: "s-nakaue", --format: "value(name)", PROJECT_ID_OR_NUMBER: "fastest-prod"]
2023-10-11 12:26:11,280 DEBUG    urllib3.connectionpool Starting new HTTPS connection (1): cloudresourcemanager.googleapis.com:443
2023-10-11 12:26:11,283 DEBUG    root            Caught socket error, retrying: HTTPSConnectionPool(host='cloudresourcemanager.googleapis.com', port=443): Max retries exceeded with url: /v1/projects/fastest-prod?alt=json (Caused by NewConnectionError('<urllib3.connection.HTTPSConnection object at 0x106517280>: Failed to establish a new connection: [Errno 8] nodename nor servname provided, or not known'))
2023-10-11 12:26:11,283 DEBUG    root            Retrying request to url https://cloudresourcemanager.googleapis.com/v1/projects/fastest-prod?alt=json after exception HTTPSConnectionPool(host='cloudresourcemanager.googleapis.com', port=443): Max retries exceeded with url: /v1/projects/fastest-prod?alt=json (Caused by NewConnectionError('<urllib3.connection.HTTPSConnection object at 0x106517280>: Failed to establish a new connection: [Errno 8] nodename nor servname provided, or not known'))
2023-10-11 12:26:13,449 DEBUG    urllib3.connectionpool Starting new HTTPS connection (1): cloudresourcemanager.googleapis.com:443
2023-10-11 12:26:13,451 DEBUG    root            Caught socket error, retrying: HTTPSConnectionPool(host='cloudresourcemanager.googleapis.com', port=443): Max retries exceeded with url: /v1/projects/fastest-prod?alt=json (Caused by NewConnectionError('<urllib3.connection.HTTPSConnection object at 0x106517220>: Failed to establish a new connection: [Errno 8] nodename nor servname provided, or not known'))
2023-10-11 12:26:13,451 DEBUG    root            Retrying request to url https://cloudresourcemanager.googleapis.com/v1/projects/fastest-prod?alt=json after exception HTTPSConnectionPool(host='cloudresourcemanager.googleapis.com', port=443): Max retries exceeded with url: /v1/projects/fastest-prod?alt=json (Caused by NewConnectionError('<urllib3.connection.HTTPSConnection object at 0x106517220>: Failed to establish a new connection: [Errno 8] nodename nor servname provided, or not known'))
2023-10-11 12:26:16,731 DEBUG    urllib3.connectionpool Starting new HTTPS connection (1): cloudresourcemanager.googleapis.com:443
2023-10-11 12:26:16,733 DEBUG    root            Caught socket error, retrying: HTTPSConnectionPool(host='cloudresourcemanager.googleapis.com', port=443): Max retries exceeded with url: /v1/projects/fastest-prod?alt=json (Caused by NewConnectionError('<urllib3.connection.HTTPSConnection object at 0x106517310>: Failed to establish a new connection: [Errno 8] nodename nor servname provided, or not known'))
2023-10-11 12:26:16,733 DEBUG    root            Retrying request to url https://cloudresourcemanager.googleapis.com/v1/projects/fastest-prod?alt=json after exception HTTPSConnectionPool(host='cloudresourcemanager.googleapis.com', port=443): Max retries exceeded with url: /v1/projects/fastest-prod?alt=json (Caused by NewConnectionError('<urllib3.connection.HTTPSConnection object at 0x106517310>: Failed to establish a new connection: [Errno 8] nodename nor servname provided, or not known'))
2023-10-11 12:26:23,706 DEBUG    urllib3.connectionpool Starting new HTTPS connection (1): cloudresourcemanager.googleapis.com:443
2023-10-11 12:26:23,708 DEBUG    root            Caught socket error, retrying: HTTPSConnectionPool(host='cloudresourcemanager.googleapis.com', port=443): Max retries exceeded with url: /v1/projects/fastest-prod?alt=json (Caused by NewConnectionError('<urllib3.connection.HTTPSConnection object at 0x106517340>: Failed to establish a new connection: [Errno 8] nodename nor servname provided, or not known'))
2023-10-11 12:26:23,708 DEBUG    root            Retrying request to url https://cloudresourcemanager.googleapis.com/v1/projects/fastest-prod?alt=json after exception HTTPSConnectionPool(host='cloudresourcemanager.googleapis.com', port=443): Max retries exceeded with url: /v1/projects/fastest-prod?alt=json (Caused by NewConnectionError('<urllib3.connection.HTTPSConnection object at 0x106517340>: Failed to establish a new connection: [Errno 8] nodename nor servname provided, or not known'))
2023-10-11 12:26:42,261 DEBUG    urllib3.connectionpool Starting new HTTPS connection (1): cloudresourcemanager.googleapis.com:443
2023-10-11 12:26:42,264 DEBUG    root            HTTPSConnectionPool(host='cloudresourcemanager.googleapis.com', port=443): Max retries exceeded with url: /v1/projects/fastest-prod?alt=json (Caused by NewConnectionError('<urllib3.connection.HTTPSConnection object at 0x106517370>: Failed to establish a new connection: [Errno 8] nodename nor servname provided, or not known'))
Traceback (most recent call last):
  File "/Users/s-nakaue/google-cloud-sdk/lib/third_party/urllib3/connection.py", line 159, in _new_conn
    conn = connection.create_connection(
  File "/Users/s-nakaue/google-cloud-sdk/lib/third_party/urllib3/util/connection.py", line 61, in create_connection
    for res in socket.getaddrinfo(host, port, family, socket.SOCK_STREAM):
  File "/Library/Frameworks/Python.framework/Versions/3.10/lib/python3.10/socket.py", line 955, in getaddrinfo
    for res in _socket.getaddrinfo(host, port, family, type, proto, flags):
socket.gaierror: [Errno 8] nodename nor servname provided, or not known

During handling of the above exception, another exception occurred:

Traceback (most recent call last):
  File "/Users/s-nakaue/google-cloud-sdk/lib/third_party/urllib3/connectionpool.py", line 670, in urlopen
    httplib_response = self._make_request(
  File "/Users/s-nakaue/google-cloud-sdk/lib/third_party/urllib3/connectionpool.py", line 381, in _make_request
    self._validate_conn(conn)
  File "/Users/s-nakaue/google-cloud-sdk/lib/third_party/urllib3/connectionpool.py", line 976, in _validate_conn
    conn.connect()
  File "/Users/s-nakaue/google-cloud-sdk/lib/third_party/urllib3/connection.py", line 308, in connect
    conn = self._new_conn()
  File "/Users/s-nakaue/google-cloud-sdk/lib/third_party/urllib3/connection.py", line 171, in _new_conn
    raise NewConnectionError(
urllib3.exceptions.NewConnectionError: <urllib3.connection.HTTPSConnection object at 0x106517370>: Failed to establish a new connection: [Errno 8] nodename nor servname provided, or not known

During handling of the above exception, another exception occurred:

Traceback (most recent call last):
  File "/Users/s-nakaue/google-cloud-sdk/lib/third_party/requests/adapters.py", line 439, in send
    resp = conn.urlopen(
  File "/Users/s-nakaue/google-cloud-sdk/lib/third_party/urllib3/connectionpool.py", line 724, in urlopen
    retries = retries.increment(
  File "/Users/s-nakaue/google-cloud-sdk/lib/third_party/urllib3/util/retry.py", line 439, in increment
    raise MaxRetryError(_pool, url, error or ResponseError(cause))
urllib3.exceptions.MaxRetryError: HTTPSConnectionPool(host='cloudresourcemanager.googleapis.com', port=443): Max retries exceeded with url: /v1/projects/fastest-prod?alt=json (Caused by NewConnectionError('<urllib3.connection.HTTPSConnection object at 0x106517370>: Failed to establish a new connection: [Errno 8] nodename nor servname provided, or not known'))

During handling of the above exception, another exception occurred:

Traceback (most recent call last):
  File "/Users/s-nakaue/google-cloud-sdk/lib/googlecloudsdk/calliope/cli.py", line 987, in Execute
    resources = calliope_command.Run(cli=self, args=args)
  File "/Users/s-nakaue/google-cloud-sdk/lib/googlecloudsdk/calliope/backend.py", line 809, in Run
    resources = command_instance.Run(args)
  File "/Users/s-nakaue/google-cloud-sdk/lib/surface/projects/describe.py", line 51, in Run
    return projects_api.Get(project_ref)
  File "/Users/s-nakaue/google-cloud-sdk/lib/googlecloudsdk/api_lib/cloudresourcemanager/projects_api.py", line 129, in Get
    return client.projects.Get(
  File "/Users/s-nakaue/google-cloud-sdk/lib/googlecloudsdk/third_party/apis/cloudresourcemanager/v1/cloudresourcemanager_v1_client.py", line 758, in Get
    return self._RunMethod(
  File "/Users/s-nakaue/google-cloud-sdk/lib/third_party/apitools/base/py/base_api.py", line 734, in _RunMethod
    http_response = http_wrapper.MakeRequest(
  File "/Users/s-nakaue/google-cloud-sdk/lib/third_party/apitools/base/py/http_wrapper.py", line 348, in MakeRequest
    return _MakeRequestNoRetry(
  File "/Users/s-nakaue/google-cloud-sdk/lib/third_party/apitools/base/py/http_wrapper.py", line 397, in _MakeRequestNoRetry
    info, content = http.request(
  File "/Users/s-nakaue/google-cloud-sdk/lib/googlecloudsdk/core/requests.py", line 389, in HttpRequest
    return orig_request_method(*args, **kwargs)
  File "/Users/s-nakaue/google-cloud-sdk/lib/googlecloudsdk/core/requests.py", line 473, in request
    response = self.session.request(
  File "/Users/s-nakaue/google-cloud-sdk/lib/googlecloudsdk/core/transport.py", line 251, in WrappedRequest
    response = orig_request(*modified_args, **modified_kwargs)
  File "/Users/s-nakaue/google-cloud-sdk/lib/googlecloudsdk/core/credentials/requests.py", line 106, in WrappedRequest
    response = orig_request(
  File "/Users/s-nakaue/google-cloud-sdk/lib/googlecloudsdk/core/transport.py", line 251, in WrappedRequest
    response = orig_request(*modified_args, **modified_kwargs)
  File "/Users/s-nakaue/google-cloud-sdk/lib/googlecloudsdk/core/requests.py", line 221, in WrappedRequest
    return orig_request_method(*args, **kwargs)
  File "/Users/s-nakaue/google-cloud-sdk/lib/third_party/requests/sessions.py", line 533, in request
    resp = self.send(prep, **send_kwargs)
  File "/Users/s-nakaue/google-cloud-sdk/lib/third_party/requests/sessions.py", line 646, in send
    r = adapter.send(request, **kwargs)
  File "/Users/s-nakaue/google-cloud-sdk/lib/third_party/requests/adapters.py", line 516, in send
    raise ConnectionError(e, request=request)
requests.exceptions.ConnectionError: HTTPSConnectionPool(host='cloudresourcemanager.googleapis.com', port=443): Max retries exceeded with url: /v1/projects/fastest-prod?alt=json (Caused by NewConnectionError('<urllib3.connection.HTTPSConnection object at 0x106517370>: Failed to establish a new connection: [Errno 8] nodename nor servname provided, or not known'))
2023-10-11 12:26:42,276 ERROR    ___FILE_ONLY___ BEGIN CRASH STACKTRACE
Traceback (most recent call last):
  File "/Users/s-nakaue/google-cloud-sdk/lib/third_party/urllib3/connection.py", line 159, in _new_conn
    conn = connection.create_connection(
  File "/Users/s-nakaue/google-cloud-sdk/lib/third_party/urllib3/util/connection.py", line 61, in create_connection
    for res in socket.getaddrinfo(host, port, family, socket.SOCK_STREAM):
  File "/Library/Frameworks/Python.framework/Versions/3.10/lib/python3.10/socket.py", line 955, in getaddrinfo
    for res in _socket.getaddrinfo(host, port, family, type, proto, flags):
socket.gaierror: [Errno 8] nodename nor servname provided, or not known

During handling of the above exception, another exception occurred:

Traceback (most recent call last):
  File "/Users/s-nakaue/google-cloud-sdk/lib/third_party/urllib3/connectionpool.py", line 670, in urlopen
    httplib_response = self._make_request(
  File "/Users/s-nakaue/google-cloud-sdk/lib/third_party/urllib3/connectionpool.py", line 381, in _make_request
    self._validate_conn(conn)
  File "/Users/s-nakaue/google-cloud-sdk/lib/third_party/urllib3/connectionpool.py", line 976, in _validate_conn
    conn.connect()
  File "/Users/s-nakaue/google-cloud-sdk/lib/third_party/urllib3/connection.py", line 308, in connect
    conn = self._new_conn()
  File "/Users/s-nakaue/google-cloud-sdk/lib/third_party/urllib3/connection.py", line 171, in _new_conn
    raise NewConnectionError(
urllib3.exceptions.NewConnectionError: <urllib3.connection.HTTPSConnection object at 0x106517370>: Failed to establish a new connection: [Errno 8] nodename nor servname provided, or not known

During handling of the above exception, another exception occurred:

Traceback (most recent call last):
  File "/Users/s-nakaue/google-cloud-sdk/lib/third_party/requests/adapters.py", line 439, in send
    resp = conn.urlopen(
  File "/Users/s-nakaue/google-cloud-sdk/lib/third_party/urllib3/connectionpool.py", line 724, in urlopen
    retries = retries.increment(
  File "/Users/s-nakaue/google-cloud-sdk/lib/third_party/urllib3/util/retry.py", line 439, in increment
    raise MaxRetryError(_pool, url, error or ResponseError(cause))
urllib3.exceptions.MaxRetryError: HTTPSConnectionPool(host='cloudresourcemanager.googleapis.com', port=443): Max retries exceeded with url: /v1/projects/fastest-prod?alt=json (Caused by NewConnectionError('<urllib3.connection.HTTPSConnection object at 0x106517370>: Failed to establish a new connection: [Errno 8] nodename nor servname provided, or not known'))

During handling of the above exception, another exception occurred:

Traceback (most recent call last):
  File "/Users/s-nakaue/google-cloud-sdk/lib/googlecloudsdk/command_lib/crash_handling.py", line 191, in Wrapper
    target_function(*args, **kwargs)
  File "/Users/s-nakaue/google-cloud-sdk/lib/googlecloudsdk/gcloud_main.py", line 186, in main
    gcloud_cli.Execute()
  File "/Users/s-nakaue/google-cloud-sdk/lib/googlecloudsdk/calliope/cli.py", line 1013, in Execute
    self._HandleAllErrors(exc, command_path_string, specified_arg_names)
  File "/Users/s-nakaue/google-cloud-sdk/lib/googlecloudsdk/calliope/cli.py", line 1050, in _HandleAllErrors
    exceptions.HandleError(exc, command_path_string, self.__known_error_handler)
  File "/Users/s-nakaue/google-cloud-sdk/lib/googlecloudsdk/calliope/exceptions.py", line 549, in HandleError
    core_exceptions.reraise(exc)
  File "/Users/s-nakaue/google-cloud-sdk/lib/googlecloudsdk/core/exceptions.py", line 146, in reraise
    six.reraise(type(exc_value), exc_value, tb)
  File "/Users/s-nakaue/google-cloud-sdk/lib/third_party/six/__init__.py", line 693, in reraise
    raise value
  File "/Users/s-nakaue/google-cloud-sdk/lib/googlecloudsdk/calliope/cli.py", line 987, in Execute
    resources = calliope_command.Run(cli=self, args=args)
  File "/Users/s-nakaue/google-cloud-sdk/lib/googlecloudsdk/calliope/backend.py", line 809, in Run
    resources = command_instance.Run(args)
  File "/Users/s-nakaue/google-cloud-sdk/lib/surface/projects/describe.py", line 51, in Run
    return projects_api.Get(project_ref)
  File "/Users/s-nakaue/google-cloud-sdk/lib/googlecloudsdk/api_lib/cloudresourcemanager/projects_api.py", line 129, in Get
    return client.projects.Get(
  File "/Users/s-nakaue/google-cloud-sdk/lib/googlecloudsdk/third_party/apis/cloudresourcemanager/v1/cloudresourcemanager_v1_client.py", line 758, in Get
    return self._RunMethod(
  File "/Users/s-nakaue/google-cloud-sdk/lib/third_party/apitools/base/py/base_api.py", line 734, in _RunMethod
    http_response = http_wrapper.MakeRequest(
  File "/Users/s-nakaue/google-cloud-sdk/lib/third_party/apitools/base/py/http_wrapper.py", line 348, in MakeRequest
    return _MakeRequestNoRetry(
  File "/Users/s-nakaue/google-cloud-sdk/lib/third_party/apitools/base/py/http_wrapper.py", line 397, in _MakeRequestNoRetry
    info, content = http.request(
  File "/Users/s-nakaue/google-cloud-sdk/lib/googlecloudsdk/core/requests.py", line 389, in HttpRequest
    return orig_request_method(*args, **kwargs)
  File "/Users/s-nakaue/google-cloud-sdk/lib/googlecloudsdk/core/requests.py", line 473, in request
    response = self.session.request(
  File "/Users/s-nakaue/google-cloud-sdk/lib/googlecloudsdk/core/transport.py", line 251, in WrappedRequest
    response = orig_request(*modified_args, **modified_kwargs)
  File "/Users/s-nakaue/google-cloud-sdk/lib/googlecloudsdk/core/credentials/requests.py", line 106, in WrappedRequest
    response = orig_request(
  File "/Users/s-nakaue/google-cloud-sdk/lib/googlecloudsdk/core/transport.py", line 251, in WrappedRequest
    response = orig_request(*modified_args, **modified_kwargs)
  File "/Users/s-nakaue/google-cloud-sdk/lib/googlecloudsdk/core/requests.py", line 221, in WrappedRequest
    return orig_request_method(*args, **kwargs)
  File "/Users/s-nakaue/google-cloud-sdk/lib/third_party/requests/sessions.py", line 533, in request
    resp = self.send(prep, **send_kwargs)
  File "/Users/s-nakaue/google-cloud-sdk/lib/third_party/requests/sessions.py", line 646, in send
    r = adapter.send(request, **kwargs)
  File "/Users/s-nakaue/google-cloud-sdk/lib/third_party/requests/adapters.py", line 516, in send
    raise ConnectionError(e, request=request)
requests.exceptions.ConnectionError: HTTPSConnectionPool(host='cloudresourcemanager.googleapis.com', port=443): Max retries exceeded with url: /v1/projects/fastest-prod?alt=json (Caused by NewConnectionError('<urllib3.connection.HTTPSConnection object at 0x106517370>: Failed to establish a new connection: [Errno 8] nodename nor servname provided, or not known'))
2023-10-11 12:26:42,279 ERROR    root            gcloud crashed (ConnectionError): HTTPSConnectionPool(host='cloudresourcemanager.googleapis.com', port=443): Max retries exceeded with url: /v1/projects/fastest-prod?alt=json (Caused by NewConnectionError('<urllib3.connection.HTTPSConnection object at 0x106517370>: Failed to establish a new connection: [Errno 8] nodename nor servname provided, or not known'))
2023-10-11 12:26:42,285 INFO     ___FILE_ONLY___ 
If you would like to report this issue, please run the following command:

2023-10-11 12:26:42,286 INFO     ___FILE_ONLY___   gcloud feedback

2023-10-11 12:26:42,286 INFO     ___FILE_ONLY___ 
To check gcloud for common problems, please run the following command:

2023-10-11 12:26:42,286 INFO     ___FILE_ONLY___   gcloud info --run-diagnostics

2023-10-11 12:26:42,291 DEBUG    root            Metrics reporting process started...
